Workbook

Sheet Data
A1: Invoice Num | B1: Vendor | C1: Company | D1: Month | E1: Invoice Date | F1: Due Date | G1: Payment Date | H1: Status | I1: Invoice Amt USD | J1: Outstanding USD | K1: Days to Pay | L1: Aging Bucket | M1: Days Past Due | N1: Late Payment | O1: Disc Captured | P1: Disc Missed | Q1: Blocked 30d | R1: In Review 15d | S1: Issue Type | T1: Urgency
A2: INV-1001 | B2: Office Supply Co | C2: US01 | D2: Jan-25 | E2: 2025-01-02 | F2: 2025-02-02 | G2: 2025-02-04 | H2: Paid | I2: 525.67 | J2: 0 | K2: 32 | L2: Current | N2: =TRUE() -> TRUE | O2: 0 | P2: 0 | Q2: =FALSE() -> FALSE | R2: =FALSE() -> FALSE | S2: Late Payment | T2: Yellow
A3: INV-1002 | B3: Northside Transport | C3: US02 | D3: Jan-25 | E3: 2025-01-02 | F3: 2025-02-02 | G3: 2025-01-29 | H3: Paid | I3: 2623.07 | J3: 0 | K3: 26 | L3: Current | N3: =FALSE() -> FALSE | O3: 0 | P3: 0 | Q3: =FALSE() -> FALSE | R3: =FALSE() -> FALSE
A4: INV-1003 | B4: Continental Freight | C4: US02 | D4: Jan-25 | E4: 2025-01-02 | F4: 2025-02-02 | G4: 2025-01-11 | H4: Partially Paid | I4: 3342.31 | J4: 1336.92 | L4: 90+ Days | M4: 148 | N4: =FALSE() -> FALSE | O4: 0 | P4: 66.85 | Q4: =FALSE() -> FALSE | R4: =FALSE() -> FALSE | S4: Missed Discount | T4: Amber
A5: INV-1004 | B5: Northside Transport | C5: US02 | D5: Jan-25 | E5: 2025-01-03 | F5: 2025-02-05 | G5: 2025-02-07 | H5: Paid | I5: 2363.08 | J5: 0 | K5: 32 | L5: Current | N5: =TRUE() -> TRUE | O5: 0 | P5: 0 | Q5: =FALSE() -> FALSE | R5: =FALSE() -> FALSE | S5: Late Payment | T5: Yellow
A6: INV-1005 | B6: EuroFreight GmbH | C6: US02 | D6: Jan-25 | E6: 2025-01-07 | F6: 2025-02-07 | G6: 2025-01-21 | H6: Paid | I6: 1905.51 | J6: 0 | K6: 13 | L6: Current | N6: =FALSE() -> FALSE | O6: 0 | P6: 0 | Q6: =FALSE() -> FALSE | R6: =FALSE() -> FALSE
A7: INV-1006 | B7: IT Services Group | C7: US01 | D7: Jan-25 | E7: 2025-01-08 | F7: 2025-02-23 | G7: 2025-02-02 | H7: Paid | I7: 1337.83 | J7: 0 | K7: 24 | L7: Current | N7: =FALSE() -> FALSE | O7: 0 | P7: 0 | Q7: =FALSE() -> FALSE | R7: =FALSE() -> FALSE
A8: INV-1007 | B8: Logistics Partners | C8: US02 | D8: Jan-25 | E8: 2025-01-09 | F8: 2025-02-09 | G8: 2025-01-18 | H8: Paid | I8: 1444.45 | J8: 0 | K8: 8 | L8: Current | N8: =FALSE() -> FALSE | O8: 0 | P8: 0 | Q8: =FALSE() -> FALSE | R8: =FALSE() -> FALSE
A9: INV-1008 | B9: Logistics Partners | C9: US02 | D9: Jan-25 | E9: 2025-01-09 | F9: 2025-02-09 | G9: 2025-01-15 | H9: Paid | I9: 2542.85 | J9: 0 | K9: 5 | L9: Current | N9: =FALSE() -> FALSE | O9: 0 | P9: 0 | Q9: =FALSE() -> FALSE | R9: =FALSE() -> FALSE
A10: INV-1009 | B10: West Coast Paper | C10: US01 | D10: Jan-25 | E10: 2025-01-09 | F10: 2025-01-25 | H10: Blocked | I10: 567.87 | J10: 567.87 | L10: 90+ Days | M10: 156 | N10: =FALSE() -> FALSE | O10: 0 | P10: 0 | Q10: =TRUE() -> TRUE | R10: =FALSE() -> FALSE | S10: Blocked Over 30 Days | T10: Red
A11: INV-1010 | B11: Suministros MX | C11: MX01 | D11: Jan-25 | E11: 2025-01-15 | F11: 2025-02-15 | H11: Blocked | I11: 407.86 | J11: 407.86 | L11: 90+ Days | M11: 135 | N11: =FALSE() -> FALSE | O11: 0 | P11: 0 | Q11: =TRUE() -> TRUE | R11: =FALSE() -> FALSE | S11: Blocked Over 30 Days | T11: Red
A12: INV-1011 | B12: West Coast Paper | C12: US01 | D12: Jan-25 | E12: 2025-01-16 | F12: 2025-02-01 | G12: 2025-01-30 | H12: Paid | I12: 410.58 | J12: 0 | K12: 13 | L12: Current | N12: =FALSE() -> FALSE | O12: 0 | P12: 0 | Q12: =FALSE() -> FALSE | R12: =FALSE() -> FALSE
A13: INV-1012 | B13: Vendor One Foods | C13: US01 | D13: Jan-25 | E13: 2025-01-18 | F13: 2025-02-19 | G13: 2025-02-10 | H13: Paid | I13: 1478.39 | J13: 0 | K13: 21 | L13: Current | N13: =FALSE() -> FALSE | O13: 0 | P13: 0 | Q13: =FALSE() -> FALSE | R13: =FALSE() -> FALSE
A14: INV-1013 | B14: Cleaning Solutions | C14: US02 | D14: Jan-25 | E14: 2025-01-19 | F14: 2025-02-19 | G14: 2025-02-16 | H14: Paid | I14: 379.47 | J14: 0 | K14: 27 | L14: Current | N14: =FALSE() -> FALSE | O14: 0 | P14: 0 | Q14: =FALSE() -> FALSE | R14: =FALSE() -> FALSE
A15: INV-1014 | B15: City Utilities | C15: US01 | D15: Jan-25 | E15: 2025-01-20 | F15: 2025-02-05 | H15: Blocked | I15: 651.71 | J15: 651.71 | L15: 90+ Days | M15: 145 | N15: =FALSE() -> FALSE | O15: 0 | P15: 0 | Q15: =TRUE() -> TRUE | R15: =FALSE() -> FALSE | S15: Blocked Over 30 Days | T15: Red
A16: INV-1015 | B16: Fresh Beverages Inc | C16: US01 | D16: Jan-25 | E16: 2025-01-23 | F16: 2025-02-23 | G16: 2025-02-05 | H16: Paid | I16: 2604.2 | J16: 0 | K16: 12 | L16: Current | N16: =FALSE() -> FALSE | O16: 0 | P16: 0 | Q16: =FALSE() -> FALSE | R16: =FALSE() -> FALSE
A17: INV-1016 | B17: Metro Packaging | C17: US02 | D17: Jan-25 | E17: 2025-01-24 | F17: 2025-02-26 | G17: 2025-02-05 | H17: Paid | I17: 962.83 | J17: 0 | K17: 9 | L17: Current | N17: =FALSE() -> FALSE | O17: 19.26 | P17: 0 | Q17: =FALSE() -> FALSE | R17: =FALSE() -> FALSE
A18: INV-1017 | B18: Alpha Facilities Mgmt | C18: US03 | D18: Jan-25 | E18: 2025-01-24 | F18: 2025-02-26 | G18: 2025-02-04 | H18: Paid | I18: 700.72 | J18: 0 | K18: 8 | L18: Current | N18: =FALSE() -> FALSE | O18: 0 | P18: 0 | Q18: =FALSE() -> FALSE | R18: =FALSE() -> FALSE
A19: INV-1018 | B19: Packaging World | C19: US02 | D19: Jan-25 | E19: 2025-01-25 | F19: 2025-02-26 | H19: In Review | I19: 482.87 | J19: 482.87 | L19: 90+ Days | M19: 124 | N19: =FALSE() -> FALSE | O19: 0 | P19: 0 | Q19: =FALSE() -> FALSE | R19: =TRUE() -> TRUE | S19: In Review Over 15 Days | T19: Amber
A20: INV-1019 | B20: Continental Freight | C20: US02 | D20: Jan-25 | E20: 2025-01-26 | F20: 2025-02-26 | G20: 2025-02-22 | H20: Paid | I20: 3170.94 | J20: 0 | K20: 26 | L20: Current | N20: =FALSE() -> FALSE | O20: 0 | P20: 63.42 | Q20: =FALSE() -> FALSE | R20: =FALSE() -> FALSE | S20: Missed Discount | T20: Amber
A21: INV-1020 | B21: West Coast Paper | C21: US01 | D21: Feb-25 | E21: 2025-02-03 | F21: 2025-02-19 | G21: 2025-02-14 | H21: Paid | I21: 471.21 | J21: 0 | K21: 10 | L21: Current | N21: =FALSE() -> FALSE | O21: 0 | P21: 0 | Q21: =FALSE() -> FALSE | R21: =FALSE() -> FALSE
A22: INV-1021 | B22: Packaging World | C22: US02 | D22: Feb-25 | E22: 2025-02-04 | F22: 2025-03-07 | H22: Voided | I22: 0 | J22: 0 | L22: Current | N22: =FALSE() -> FALSE | O22: 0 | P22: 0 | Q22: =FALSE() -> FALSE | R22: =FALSE() -> FALSE | S22: Voided Invoice | T22: Yellow
A23: INV-1022 | B23: Vendor One Foods | C23: US01 | D23: Feb-25 | E23: 2025-02-04 | F23: 2025-03-07 | G23: 2025-02-14 | H23: Paid | I23: 3926.93 | J23: 0 | K23: 9 | L23: Current | N23: =FALSE() -> FALSE | O23: 0 | P23: 0 | Q23: =FALSE() -> FALSE | R23: =FALSE() -> FALSE
A24: INV-1023 | B24: Alpha Facilities Mgmt | C24: US03 | D24: Feb-25 | E24: 2025-02-04 | F24: 2025-03-07 | H24: Overdue | I24: 811.75 | J24: 811.75 | L24: 90+ Days | M24: 115 | N24: =FALSE() -> FALSE | O24: 0 | P24: 0 | Q24: =FALSE() -> FALSE | R24: =FALSE() -> FALSE | S24: Overdue Invoice | T24: Red
A25: INV-1024 | B25: Packaging World | C25: US02 | D25: Feb-25 | E25: 2025-02-05 | F25: 2025-03-08 | G25: 2025-03-06 | H25: Paid | I25: 804.33 | J25: 0 | K25: 28 | L25: Current | N25: =FALSE() -> FALSE | O25: 0 | P25: 0 | Q25: =FALSE() -> FALSE | R25: =FALSE() -> FALSE
A26: INV-1025 | B26: Fresh Beverages Inc | C26: US01 | D26: Feb-25 | E26: 2025-02-05 | F26: 2025-03-08 | G26: 2025-02-27 | H26: Paid | I26: 1550.73 | J26: 0 | K26: 21 | L26: Current | N26: =FALSE() -> FALSE | O26: 0 | P26: 0 | Q26: =FALSE() -> FALSE | R26: =FALSE() -> FALSE
A27: INV-1026 | B27: IT Services Group | C27: US01 | D27: Feb-25 | E27: 2025-02-05 | F27: 2025-03-23 | G27: 2025-03-14 | H27: Paid | I27: 874.95 | J27: 0 | K27: 36 | L27: Current | N27: =FALSE() -> FALSE | O27: 0 | P27: 0 | Q27: =FALSE() -> FALSE | R27: =FALSE() -> FALSE
A28: INV-1027 | B28: Office Supply Co | C28: US01 | D28: Feb-25 | E28: 2025-02-06 | F28: 2025-03-09 | H28: Overdue | I28: 418.56 | J28: 418.56 | L28: 90+ Days | M28: 113 | N28: =FALSE() -> FALSE | O28: 0 | P28: 0 | Q28: =FALSE() -> FALSE | R28: =FALSE() -> FALSE | S28: Overdue Invoice | T28: Red
A29: INV-1028 | B29: Metro Packaging | C29: US02 | D29: Feb-25 | E29: 2025-02-08 | F29: 2025-03-12 | G29: 2025-02-22 | H29: Paid | I29: 609.56 | J29: 0 | K29: 12 | L29: Current | N29: =FALSE() -> FALSE | O29: 0 | P29: 12.19 | Q29: =FALSE() -> FALSE | R29: =FALSE() -> FALSE | S29: Missed Discount | T29: Amber
A30: INV-1029 | B30: Suministros MX | C30: MX01 | D30: Feb-25 | E30: 2025-02-09 | F30: 2025-03-12 | H30: Voided | I30: 0 | J30: 0 | L30: Current | N30: =FALSE() -> FALSE | O30: 0 | P30: 0 | Q30: =FALSE() -> FALSE | R30: =FALSE() -> FALSE | S30: Voided Invoice | T30: Yellow
A31: INV-1030 | B31: Office Supply Co | C31: US01 | D31: Feb-25 | E31: 2025-02-10 | F31: 2025-03-13 | G31: 2025-03-25 | H31: Paid | I31: 380.45 | J31: 0 | K31: 42 | L31: Current | N31: =TRUE() -> TRUE | O31: 0 | P31: 0 | Q31: =FALSE() -> FALSE | R31: =FALSE() -> FALSE | S31: Late Payment | T31: Yellow
A32: INV-1031 | B32: City Utilities | C32: US01 | D32: Feb-25 | E32: 2025-02-10 | F32: 2025-02-26 | H32: Overdue | I32: 661.57 | J32: 661.57 | L32: 90+ Days | M32: 124 | N32: =FALSE() -> FALSE | O32: 0 | P32: 0 | Q32: =FALSE() -> FALSE | R32: =FALSE() -> FALSE | S32: Overdue Invoice | T32: Red
A33: INV-1032 | B33: EuroFreight GmbH | C33: US02 | D33: Feb-25 | E33: 2025-02-11 | F33: 2025-03-14 | H33: Overdue | I33: 2242.02 | J33: 2242.02 | L33: 90+ Days | M33: 108 | N33: =FALSE() -> FALSE | O33: 0 | P33: 0 | Q33: =FALSE() -> FALSE | R33: =FALSE() -> FALSE | S33: Overdue Invoice | T33: Red
A34: INV-1033 | B34: Fresh Beverages Inc | C34: US01 | D34: Feb-25 | E34: 2025-02-13 | F34: 2025-03-16 | G34: 2025-03-11 | H34: Paid | I34: 4371.46 | J34: 0 | K34: 25 | L34: Current | N34: =FALSE() -> FALSE | O34: 0 | P34: 0 | Q34: =FALSE() -> FALSE | R34: =FALSE() -> FALSE
A35: INV-1034 | B35: IT Services Group | C35: US01 | D35: Feb-25 | E35: 2025-02-19 | F35: 2025-04-06 | H35: Overdue | I35: 1530.64 | J35: 1530.64 | L35: 61-90 Days | M35: 85 | N35: =FALSE() -> FALSE | O35: 0 | P35: 0 | Q35: =FALSE() -> FALSE | R35: =FALSE() -> FALSE | S35: Overdue Invoice | T35: Red
A36: INV-1035 | B36: Vendor One Foods | C36: US01 | D36: Feb-25 | E36: 2025-02-19 | F36: 2025-03-22 | H36: Overdue | I36: 1358.95 | J36: 1358.95 | L36: 90+ Days | M36: 100 | N36: =FALSE() -> FALSE | O36: 0 | P36: 0 | Q36: =FALSE() -> FALSE | R36: =FALSE() -> FALSE | S36: Overdue Invoice | T36: Red
A37: INV-1036 | B37: Metro Packaging | C37: US02 | D37: Feb-25 | E37: 2025-02-20 | F37: 2025-03-23 | H37: Overdue | I37: 691.72 | J37: 691.72 | L37: 90+ Days | M37: 99 | N37: =FALSE() -> FALSE | O37: 0 | P37: 13.83 | Q37: =FALSE() -> FALSE | R37: =FALSE() -> FALSE | S37: Missed Discount | T37: Amber
A38: INV-1037 | B38: City Utilities | C38: US01 | D38: Feb-25 | E38: 2025-02-21 | F38: 2025-03-11 | G38: 2025-03-10 | H38: Paid | I38: 673.24 | J38: 0 | K38: 14 | L38: Current | N38: =FALSE() -> FALSE | O38: 0 | P38: 0 | Q38: =FALSE() -> FALSE | R38: =FALSE() -> FALSE
A39: INV-1038 | B39: Cleaning Solutions | C39: US02 | D39: Feb-25 | E39: 2025-02-21 | F39: 2025-03-26 | H39: Voided | I39: 0 | J39: 0 | L39: Current | N39: =FALSE() -> FALSE | O39: 0 | P39: 0 | Q39: =FALSE() -> FALSE | R39: =FALSE() -> FALSE | S39: Voided Invoice | T39: Yellow
A40: INV-1039 | B40: Cleaning Solutions | C40: US02 | D40: Feb-25 | E40: 2025-02-22 | F40: 2025-03-26 | G40: 2025-03-22 | H40: Paid | I40: 426.05 | J40: 0 | K40: 26 | L40: Current | N40: =FALSE() -> FALSE | O40: 0 | P40: 0 | Q40: =FALSE() -> FALSE | R40: =FALSE() -> FALSE
...

Sheet Dashboard
B2: AP Management Dashboard
B3: Accounts Payable Operations · Jan – Jun 2025 · Project by Augusto Sander
B7: TOTAL OUTSTANDING (USD) | G7: ON-TIME PAYMENT RATE | M7: DISCOUNT CAPTURE RATE | R7: CRITICAL EXCEPTIONS
B8: ='Summary Tables'!D5 -> 77420.62 | G8: ='Summary Tables'!D7 -> 0.83098592 | M8: ='Summary Tables'!D8 -> 0.033716126 | R8: ='Summary Tables'!D9 -> 14
B9: =TEXT('Summary Tables'!D6,"0")&" invoices open" -> 61 invoices open | G9: "Target ≥ 85%" | M9: ="$"&TEXT('Summary Tables'!D10,"#,##0")&" in missed savings" -> $552 in missed savings | R9: "Blocked 30d · Voided · In Review"

Sheet Exceptions Detail
B1: Exceptions Detail
B3: Critical exception breakdown by type and company code · 14 total exceptions across 3 categories
B4: ▸ BY EXCEPTION TYPE · Company breakdown
B5: Exception Type | C5: Total | D5: US01 | E5: US02 | F5: MX01 | G5: US03 | H5: What it means
B6: Blocked 30d+ | C6: ='Summary Tables'!C58 -> 7 | D6: ='Summary Tables'!D58 -> 2 | E6: ='Summary Tables'!E58 -> 4 | F6: ='Summary Tables'!F58 -> 1 | G6: ='Summary Tables'!G58 -> 0 | H6: Invoice has been blocked from payment for 30+ days — requires urgent review
B7: In Review 15d+ | C7: ='Summary Tables'!C59 -> 4 | D7: ='Summary Tables'!D59 -> 2 | E7: ='Summary Tables'!E59 -> 2 | F7: ='Summary Tables'!F59 -> 0 | G7: ='Summary Tables'!G59 -> 0 | H7: Invoice stuck in review queue for 15+ days — SLA breach
B8: Voided | C8: ='Summary Tables'!C60 -> 3 | D8: ='Summary Tables'!D60 -> 0 | E8: ='Summary Tables'!E60 -> 2 | F8: ='Summary Tables'!F60 -> 1 | G8: ='Summary Tables'!G60 -> 0 | H8: Invoice voided — may indicate duplicate, error, or dispute
B9: TOTAL EXCEPTIONS | C9: ='Summary Tables'!D9 -> 14
B11: ▸ BY VENDOR · Which vendors are driving exceptions
B12: Vendor | C12: Blocked 30d+ | D12: In Review 15d+ | E12: Voided | F12: Total
B13: Fresh Beverages Inc | C13: =COUNTIFS(AP_Invoices[Vendor],B13,AP_Invoices[Blocked 30d],TRUE()) -> 0 | D13: =COUNTIFS(AP_Invoices[Vendor],B13,AP_Invoices[In Review 15d],TRUE()) -> 0 | E13: =COUNTIFS(AP_Invoices[Vendor],B13,AP_Invoices[Status],"Voided") -> 0 | F13: =SUM(C13:E13) -> 0
B14: Continental Freight | C14: =COUNTIFS(AP_Invoices[Vendor],B14,AP_Invoices[Blocked 30d],TRUE()) -> 1 | D14: =COUNTIFS(AP_Invoices[Vendor],B14,AP_Invoices[In Review 15d],TRUE()) -> 0 | E14: =COUNTIFS(AP_Invoices[Vendor],B14,AP_Invoices[Status],"Voided") -> 0 | F14: =SUM(C14:E14) -> 1
B15: IT Services Group | C15: =COUNTIFS(AP_Invoices[Vendor],B15,AP_Invoices[Blocked 30d],TRUE()) -> 0 | D15: =COUNTIFS(AP_Invoices[Vendor],B15,AP_Invoices[In Review 15d],TRUE()) -> 1 | E15: =COUNTIFS(AP_Invoices[Vendor],B15,AP_Invoices[Status],"Voided") -> 0 | F15: =SUM(C15:E15) -> 1
B16: Vendor One Foods | C16: =COUNTIFS(AP_Invoices[Vendor],B16,AP_Invoices[Blocked 30d],TRUE()) -> 0 | D16: =COUNTIFS(AP_Invoices[Vendor],B16,AP_Invoices[In Review 15d],TRUE()) -> 0 | E16: =COUNTIFS(AP_Invoices[Vendor],B16,AP_Invoices[Status],"Voided") -> 0 | F16: =SUM(C16:E16) -> 0
B17: Logistics Partners | C17: =COUNTIFS(AP_Invoices[Vendor],B17,AP_Invoices[Blocked 30d],TRUE()) -> 2 | D17: =COUNTIFS(AP_Invoices[Vendor],B17,AP_Invoices[In Review 15d],TRUE()) -> 0 | E17: =COUNTIFS(AP_Invoices[Vendor],B17,AP_Invoices[Status],"Voided") -> 0 | F17: =SUM(C17:E17) -> 2
B18: EuroFreight GmbH | C18: =COUNTIFS(AP_Invoices[Vendor],B18,AP_Invoices[Blocked 30d],TRUE()) -> 0 | D18: =COUNTIFS(AP_Invoices[Vendor],B18,AP_Invoices[In Review 15d],TRUE()) -> 0 | E18: =COUNTIFS(AP_Invoices[Vendor],B18,AP_Invoices[Status],"Voided") -> 0 | F18: =SUM(C18:E18) -> 0
B19: Metro Packaging | C19: =COUNTIFS(AP_Invoices[Vendor],B19,AP_Invoices[Blocked 30d],TRUE()) -> 0 | D19: =COUNTIFS(AP_Invoices[Vendor],B19,AP_Invoices[In Review 15d],TRUE()) -> 1 | E19: =COUNTIFS(AP_Invoices[Vendor],B19,AP_Invoices[Status],"Voided") -> 0 | F19: =SUM(C19:E19) -> 1
B20: Northside Transport | C20: =COUNTIFS(AP_Invoices[Vendor],B20,AP_Invoices[Blocked 30d],TRUE()) -> 0 | D20: =COUNTIFS(AP_Invoices[Vendor],B20,AP_Invoices[In Review 15d],TRUE()) -> 0 | E20: =COUNTIFS(AP_Invoices[Vendor],B20,AP_Invoices[Status],"Voided") -> 0 | F20: =SUM(C20:E20) -> 0
B21: City Utilities | C21: =COUNTIFS(AP_Invoices[Vendor],B21,AP_Invoices[Blocked 30d],TRUE()) -> 1 | D21: =COUNTIFS(AP_Invoices[Vendor],B21,AP_Invoices[In Review 15d],TRUE()) -> 0 | E21: =COUNTIFS(AP_Invoices[Vendor],B21,AP_Invoices[Status],"Voided") -> 0 | F21: =SUM(C21:E21) -> 1
B22: Suministros MX | C22: =COUNTIFS(AP_Invoices[Vendor],B22,AP_Invoices[Blocked 30d],TRUE()) -> 1 | D22: =COUNTIFS(AP_Invoices[Vendor],B22,AP_Invoices[In Review 15d],TRUE()) -> 0 | E22: =COUNTIFS(AP_Invoices[Vendor],B22,AP_Invoices[Status],"Voided") -> 1 | F22: =SUM(C22:E22) -> 2
B23: Packaging World | C23: =COUNTIFS(AP_Invoices[Vendor],B23,AP_Invoices[Blocked 30d],TRUE()) -> 0 | D23: =COUNTIFS(AP_Invoices[Vendor],B23,AP_Invoices[In Review 15d],TRUE()) -> 1 | E23: =COUNTIFS(AP_Invoices[Vendor],B23,AP_Invoices[Status],"Voided") -> 1 | F23: =SUM(C23:E23) -> 2
B24: Office Supply Co | C24: =COUNTIFS(AP_Invoices[Vendor],B24,AP_Invoices[Blocked 30d],TRUE()) -> 0 | D24: =COUNTIFS(AP_Invoices[Vendor],B24,AP_Invoices[In Review 15d],TRUE()) -> 0 | E24: =COUNTIFS(AP_Invoices[Vendor],B24,AP_Invoices[Status],"Voided") -> 0 | F24: =SUM(C24:E24) -> 0
... B27: Cleaning Solutions | C27: =COUNTIFS(AP_Invoices[Vendor],B27,AP_Invoices[Blocked 30d],TRUE()) -> 1 | D27: =COUNTIFS(AP_Invoices[Vendor],B27,AP_Invoices[In Review 15d],TRUE()) -> 0 | E27: =COUNTIFS(AP_Invoices[Vendor],B27,AP_Invoices[Status],"Voided") -> 1 | F27: =SUM(C27:E27) -> 2

Sheet Summary Tables
B1: Summary Tables — Excel Formula Engine
B3: ► KPI METRICS
B4: Metric | C4: Excel Formula | D4: Result
B5: Total Outstanding (USD) | C5: =SUM(AP_Invoices[Outstanding USD]) -> 77420.62 | D5: =SUM(AP_Invoices[Outstanding USD]) -> 77420.62 | E5: Sum of all unpaid balances
B6: Unpaid Invoice Count | C6: =COUNTIF(AP_Invoices[Outstanding USD],">"&0) -> 61 | D6: =COUNTIF(AP_Invoices[Outstanding USD],">"&0) -> 61 | E6: Invoices with outstanding > 0
B7: On-Time Payment Rate | C7: =(COUNTIFS(AP_Invoices[Late Payment],FALSE(),AP_Invoices[Status],"Paid")+COUNTIFS(AP_Invoices[Late Payment],FALSE(),AP_Invoices[Status],"Partially Paid"))/(COUNTIF(AP_Invoices[Status],"Paid")+COUNTIF(AP_Invoices[Status],"Partially Paid")) -> 0.83098592 | D7: =(COUNTIFS(AP_Invoices[Late Payment],FALSE(),AP_Invoices[Status],"Paid")+COUNTIFS(AP_Invoices[Late Payment],FALSE(),AP_Invoices[Status],"Partially Paid"))/(COUNTIF(AP_Invoices[Status],"Paid")+COUNTIF(AP_Invoices[Status],"Partially Paid")) -> 0.83098592 | E7: Paid invoices where late_payment_flag = FALSE
B8: Discount Capture Rate | C8: =SUM(AP_Invoices[Disc Captured])/(SUM(AP_Invoices[Disc Captured])+SUM(AP_Invoices[Disc Missed])) -> 0.033716126 | D8: =SUM(AP_Invoices[Disc Captured])/(SUM(AP_Invoices[Disc Captured])+SUM(AP_Invoices[Disc Missed])) -> 0.033716126 | E8: Captured ÷ (Captured + Missed)
B9: Critical Exceptions | C9: =COUNTIF(AP_Invoices[Blocked 30d],TRUE())+COUNTIF(AP_Invoices[Status],"Voided")+COUNTIF(AP_Invoices[In Review 15d],TRUE()) -> 14 | D9: =COUNTIF(AP_Invoices[Blocked 30d],TRUE())+COUNTIF(AP_Invoices[Status],"Voided")+COUNTIF(AP_Invoices[In Review 15d],TRUE()) -> 14 | E9: Blocked 30d + Voided + In Review 15d
B10: Total Missed Discount (USD) | C10: =SUM(AP_Invoices[Disc Missed]) -> 551.98 | D10: =SUM(AP_Invoices[Disc Missed]) -> 551.98 | E10: Used in KPI badge
B12: ► AGING BREAKDOWN — source for Aging chart
B13: Aging Bucket | C13: Outstanding USD
B14: Current | C14: =SUMIF(AP_Invoices[Aging Bucket],B14,AP_Invoices[Outstanding USD]) -> 22996.67
B15: 0-30 Days | C15: =SUMIF(AP_Invoices[Aging Bucket],B15,AP_Invoices[Outstanding USD]) -> 8047.98
B16: 31-60 Days | C16: =SUMIF(AP_Invoices[Aging Bucket],B16,AP_Invoices[Outstanding USD]) -> 13989.01
B17: 61-90 Days | C17: =SUMIF(AP_Invoices[Aging Bucket],B17,AP_Invoices[Outstanding USD]) -> 21000.23
B18: 90+ Days | C18: =SUMIF(AP_Invoices[Aging Bucket],B18,AP_Invoices[Outstanding USD]) -> 11386.73
B20: ► DISCOUNT BY MONTH — source for Discount chart
B21: Month | C21: Captured USD | D21: Missed USD
B22: Jan-25 | C22: =SUMIF(AP_Invoices[Month],B22,AP_Invoices[Disc Captured]) -> 19.26 | D22: =SUMIF(AP_Invoices[Month],B22,AP_Invoices[Disc Missed]) -> 130.27
B23: Feb-25 | C23: =SUMIF(AP_Invoices[Month],B23,AP_Invoices[Disc Captured]) -> 0 | D23: =SUMIF(AP_Invoices[Month],B23,AP_Invoices[Disc Missed]) -> 82.49
B24: Mar-25 | C24: =SUMIF(AP_Invoices[Month],B24,AP_Invoices[Disc Captured]) -> 0 | D24: =SUMIF(AP_Invoices[Month],B24,AP_Invoices[Disc Missed]) -> 85.69
B25: Apr-25 | C25: =SUMIF(AP_Invoices[Month],B25,AP_Invoices[Disc Captured]) -> 0 | D25: =SUMIF(AP_Invoices[Month],B25,AP_Invoices[Disc Missed]) -> 80.82
B26: May-25 | C26: =SUMIF(AP_Invoices[Month],B26,AP_Invoices[Disc Captured]) -> 0 | D26: =SUMIF(AP_Invoices[Month],B26,AP_Invoices[Disc Missed]) -> 115.21
B27: Jun-25 | C27: =SUMIF(AP_Invoices[Month],B27,AP_Invoices[Disc Captured]) -> 0 | D27: =SUMIF(AP_Invoices[Month],B27,AP_Invoices[Disc Missed]) -> 57.5
B29: ▸ ► ON-TIME RATE BY MONTH — source for Trend chart
B30: Month | C30: Paid On-Time | D30: Total Paid | E30: On-Time Rate %
B31: Jan-25 | C31: =COUNTIFS(AP_Invoices[Month],B31,AP_Invoices[Late Payment],FALSE(),AP_Invoices[Status],"Paid") -> 12 | D31: =COUNTIFS(AP_Invoices[Month],B31,AP_Invoices[Status],"Paid") -> 14 | E31: =IF(D31>0,C31/D31,0) -> 0.85714286
B32: Feb-25 | C32: =COUNTIFS(AP_Invoices[Month],B32,AP_Invoices[Late Payment],FALSE(),AP_Invoices[Status],"Paid") -> 11 | D32: =COUNTIFS(AP_Invoices[Month],B32,AP_Invoices[Status],"Paid") -> 12 | E32: =IF(D32>0,C32/D32,0) -> 0.91666667
B33: Mar-25 | C33: =COUNTIFS(AP_Invoices[Month],B33,AP_Invoices[Late Payment],FALSE(),AP_Invoices[Status],"Paid") -> 6 | D33: =COUNTIFS(AP_Invoices[Month],B33,AP_Invoices[Status],"Paid") -> 9 | E33: =IF(D33>0,C33/D33,0) -> 0.66666667
B34: Apr-25 | C34: =COUNTIFS(AP_Invoices[Month],B34,AP_Invoices[Late Payment],FALSE(),AP_Invoices[Status],"Paid") -> 9 | D34: =COUNTIFS(AP_Invoices[Month],B34,AP_Invoices[Status],"Paid") -> 12 | E34: =IF(D34>0,C34/D34,0) -> 0.75
B35: May-25 | C35: =COUNTIFS(AP_Invoices[Month],B35,AP_Invoices[Late Payment],FALSE(),AP_Invoices[Status],"Paid") -> 10 | D35: =COUNTIFS(AP_Invoices[Month],B35,AP_Invoices[Status],"Paid") -> 13 | E35: =IF(D35>0,C35/D35,0) -> 0.76923077
B36: Jun-25 | C36: =COUNTIFS(AP_Invoices[Month],B36,AP_Invoices[Late Payment],FALSE(),AP_Invoices[Status],"Paid") -> 6 | D36: =COUNTIFS(AP_Invoices[Month],B36,AP_Invoices[Status],"Paid") -> 6 | E36: =IF(D36>0,C36/D36,0) -> 1
B38: ▸ ► VENDOR SUMMARY — source for Vendor Analysis tab
B39: Vendor | C39: Outstanding USD | D39: Invoice Count | E39: Overdue Count | F39: Disc Missed USD | G39: Exceptions
B40: Fresh Beverages Inc | C40: =SUMIF(AP_Invoices[Vendor],B40,AP_Invoices[Outstanding USD]) -> 13779.17 | D40: =COUNTIF(AP_Invoices[Vendor],B40) -> 9 | E40: =COUNTIFS(AP_Invoices[Vendor],B40,AP_Invoices[Status],"Overdue")+COUNTIFS(AP_Invoices[Vendor],B40,AP_Invoices[Status],"Blocked")+COUNTIFS(AP_Invoices[Vendor],B40,AP_Invoices[Status],"In Review")+COUNTIFS(AP_Invoices[Vendor],B40,AP_Invoices[Status],"Partially Paid",AP_Invoices[Days Past Due],">"&0) -> 3 | F40: =SUMIF(AP_Invoices[Vendor],B40,AP_Invoices[Disc Missed]) -> 0 | G40: =COUNTIFS(AP_Invoices[Vendor],B40,AP_Invoices[Blocked 30d],TRUE())+COUNTIFS(AP_Invoices[Vendor],B40,AP_Invoices[Status],"Voided")+COUNTIFS(AP_Invoices[Vendor],B40,AP_Invoices[In Review 15d],TRUE()) -> 0
B41: Continental Freight | C41: =SUMIF(AP_Invoices[Vendor],B41,AP_Invoices[Outstanding USD]) -> 11030.14 | D41: =COUNTIF(AP_Invoices[Vendor],B41) -> 9 | E41: =COUNTIFS(AP_Invoices[Vendor],B41,AP_Invoices[Status],"Overdue")+COUNTIFS(AP_Invoices[Vendor],B41,AP_Invoices[Status],"Blocked")+COUNTIFS(AP_Invoices[Vendor],B41,AP_Invoices[Status],"In Review")+COUNTIFS(AP_Invoices[Vendor],B41,AP_Invoices[Status],"Partially Paid",AP_Invoices[Days Past Due],">"&0) -> 4 | F41: =SUMIF(AP_Invoices[Vendor],B41,AP_Invoices[Disc Missed]) -> 451.08 | G41: =COUNTIFS(AP_Invoices[Vendor],B41,AP_Invoices[Blocked 30d],TRUE())+COUNTIFS(AP_Invoices[Vendor],B41,AP_Invoices[Status],"Voided")+COUNTIFS(AP_Invoices[Vendor],B41,AP_Invoices[In Review 15d],TRUE()) -> 1
B42: IT Services Group | C42: =SUMIF(AP_Invoices[Vendor],B42,AP_Invoices[Outstanding USD]) -> 8700.57 | D42: =COUNTIF(AP_Invoices[Vendor],B42) -> 9 | E42: =COUNTIFS(AP_Invoices[Vendor],B42,AP_Invoices[Status],"Overdue")+COUNTIFS(AP_Invoices[Vendor],B42,AP_Invoices[Status],"Blocked")+COUNTIFS(AP_Invoices[Vendor],B42,AP_Invoices[Status],"In Review")+COUNTIFS(AP_Invoices[Vendor],B42,AP_Invoices[Status],"Partially Paid",AP_Invoices[Days Past Due],">"&0) -> 4 | F42: =SUMIF(AP_Invoices[Vendor],B42,AP_Invoices[Disc Missed]) -> 0 | G42: =COUNTIFS(AP_Invoices[Vendor],B42,AP_Invoices[Blocked 30d],TRUE())+COUNTIFS(AP_Invoices[Vendor],B42,AP_Invoices[Status],"Voided")+COUNTIFS(AP_Invoices[Vendor],B42,AP_Invoices[In Review 15d],TRUE()) -> 1
B43: Vendor One Foods | C43: =SUMIF(AP_Invoices[Vendor],B43,AP_Invoices[Outstanding USD]) -> 7208.24 | D43: =COUNTIF(AP_Invoices[Vendor],B43) -> 9 | E43: =COUNTIFS(AP_Invoices[Vendor],B43,AP_Invoices[Status],"Overdue")+COUNTIFS(AP_Invoices[Vendor],B43,AP_Invoices[Status],"Blocked")+COUNTIFS(AP_Invoices[Vendor],B43,AP_Invoices[Status],"In Review")+COUNTIFS(AP_Invoices[Vendor],B43,AP_Invoices[Status],"Partially Paid",AP_Invoices[Days Past Due],">"&0) -> 2 | F43: =SUMIF(AP_Invoices[Vendor],B43,AP_Invoices[Disc Missed]) -> 0 | G43: =COUNTIFS(AP_Invoices[Vendor],B43,AP_Invoices[Blocked 30d],TRUE())+COUNTIFS(AP_Invoices[Vendor],B43,AP_Invoices[Status],"Voided")+COUNTIFS(AP_Invoices[Vendor],B43,AP_Invoices[In Review 15d],TRUE()) -> 0
B44: Logistics Partners | C44: =SUMIF(AP_Invoices[Vendor],B44,AP_Invoices[Outstanding USD]) -> 6447.85 | D44: =COUNTIF(AP_Invoices[Vendor],B44) -> 10 | E44: =COUNTIFS(AP_Invoices[Vendor],B44,AP_Invoices[Status],"Overdue")+COUNTIFS(AP_Invoices[Vendor],B44,AP_Invoices[Status],"Blocked")+COUNTIFS(AP_Invoices[Vendor],B44,AP_Invoices[Status],"In Review")+COUNTIFS(AP_Invoices[Vendor],B44,AP_Invoices[Status],"Partially Paid",AP_Invoices[Days Past Due],">"&0) -> 2 | F44: =SUMIF(AP_Invoices[Vendor],B44,AP_Invoices[Disc Missed]) -> 0 | G44: =COUNTIFS(AP_Invoices[Vendor],B44,AP_Invoices[Blocked 30d],TRUE())+COUNTIFS(AP_Invoices[Vendor],B44,AP_Invoices[Status],"Voided")+COUNTIFS(AP_Invoices[Vendor],B44,AP_Invoices[In Review 15d],TRUE()) -> 2
B45: EuroFreight GmbH | C45: =SUMIF(AP_Invoices[Vendor],B45,AP_Invoices[Outstanding USD]) -> 5696.25 | D45: =COUNTIF(AP_Invoices[Vendor],B45) -> 6 | E45: =COUNTIFS(AP_Invoices[Vendor],B45,AP_Invoices[Status],"Overdue")+COUNTIFS(AP_Invoices[Vendor],B45,AP_Invoices[Status],"Blocked")+COUNTIFS(AP_Invoices[Vendor],B45,AP_Invoices[Status],"In Review")+COUNTIFS(AP_Invoices[Vendor],B45,AP_Invoices[Status],"Partially Paid",AP_Invoices[Days Past Due],">"&0) -> 2 | F45: =SUMIF(AP_Invoices[Vendor],B45,AP_Invoices[Disc Missed]) -> 0 | G45: =COUNTIFS(AP_Invoices[Vendor],B45,AP_Invoices[Blocked 30d],TRUE())+COUNTIFS(AP_Invoices[Vendor],B45,AP_Invoices[Status],"Voided")+COUNTIFS(AP_Invoices[Vendor],B45,AP_Invoices[In Review 15d],TRUE()) -> 0
...

Sheet Vendor Analysis
B1: Vendor Analysis
B3: Outstanding balance, overdue exposure, and discount performance by vendor — sorted by outstanding balance (highest first)
B4: Vendor | C4: Outstanding USD | D4: Invoice Count | E4: Overdue Count | F4: Disc Missed USD | G4: Exceptions | H4: Risk Signal
B5: ='Summary Tables'!B40 -> Fresh Beverages Inc | C5: ='Summary Tables'!C40 -> 13779.17 | D5: ='Summary Tables'!D40 -> 9 | E5: ='Summary Tables'!E40 -> 3 | F5: ='Summary Tables'!F40 -> 0 | G5: ='Summary Tables'!G40 -> 0 | H5: =IF(AND('Summary Tables'!G40>=5,'Summary Tables'!F40>0),"⚠ High — Exceptions + Missed Discount",IF('Summary Tables'!G40>=5,"⚠ High — Multiple Exceptions",IF('Summary Tables'!F40>50,"⚠ Review — Missed Discount",IF('Summary Tables'!C40>10000,"► Monitor — High Balance","✓ Normal")))) -> ► Monitor — High Balance
B6: ='Summary Tables'!B41 -> Continental Freight | C6: ='Summary Tables'!C41 -> 11030.14 | D6: ='Summary Tables'!D41 -> 9 | E6: ='Summary Tables'!E41 -> 4 | F6: ='Summary Tables'!F41 -> 451.08 | G6: ='Summary Tables'!G41 -> 1 | H6: =IF(AND('Summary Tables'!G41>=5,'Summary Tables'!F41>0),"⚠ High — Exceptions + Missed Discount",IF('Summary Tables'!G41>=5,"⚠ High — Multiple Exceptions",IF('Summary Tables'!F41>50,"⚠ Review — Missed Discount",IF('Summary Tables'!C41>10000,"► Monitor — High Balance","✓ Normal")))) -> ⚠ Review — Missed Discount
B7: ='Summary Tables'!B42 -> IT Services Group | C7: ='Summary Tables'!C42 -> 8700.57 | D7: ='Summary Tables'!D42 -> 9 | E7: ='Summary Tables'!E42 -> 4 | F7: ='Summary Tables'!F42 -> 0 | G7: ='Summary Tables'!G42 -> 1 | H7: =IF(AND('Summary Tables'!G42>=5,'Summary Tables'!F42>0),"⚠ High — Exceptions + Missed Discount",IF('Summary Tables'!G42>=5,"⚠ High — Multiple Exceptions",IF('Summary Tables'!F42>50,"⚠ Review — Missed Discount",IF('Summary Tables'!C42>10000,"► Monitor — High Balance","✓ Normal")))) -> ✓ Normal
B8: ='Summary Tables'!B43 -> Vendor One Foods | C8: ='Summary Tables'!C43 -> 7208.24 | D8: ='Summary Tables'!D43 -> 9 | E8: ='Summary Tables'!E43 -> 2 | F8: ='Summary Tables'!F43 -> 0 | G8: ='Summary Tables'!G43 -> 0 | H8: =IF(AND('Summary Tables'!G43>=5,'Summary Tables'!F43>0),"⚠ High — Exceptions + Missed Discount",IF('Summary Tables'!G43>=5,"⚠ High — Multiple Exceptions",IF('Summary Tables'!F43>50,"⚠ Review — Missed Discount",IF('Summary Tables'!C43>10000,"► Monitor — High Balance","✓ Normal")))) -> ✓ Normal
B9: ='Summary Tables'!B44 -> Logistics Partners | C9: ='Summary Tables'!C44 -> 6447.85 | D9: ='Summary Tables'!D44 -> 10 | E9: ='Summary Tables'!E44 -> 2 | F9: ='Summary Tables'!F44 -> 0 | G9: ='Summary Tables'!G44 -> 2 | H9: =IF(AND('Summary Tables'!G44>=5,'Summary Tables'!F44>0),"⚠ High — Exceptions + Missed Discount",IF('Summary Tables'!G44>=5,"⚠ High — Multiple Exceptions",IF('Summary Tables'!F44>50,"⚠ Review — Missed Discount",IF('Summary Tables'!C44>10000,"► Monitor — High Balance","✓ Normal")))) -> ✓ Normal
B10: ='Summary Tables'!B45 -> EuroFreight GmbH | C10: ='Summary Tables'!C45 -> 5696.25 | D10: ='Summary Tables'!D45 -> 6 | E10: ='Summary Tables'!E45 -> 2 | F10: ='Summary Tables'!F45 -> 0 | G10: ='Summary Tables'!G45 -> 0 | H10: =IF(AND('Summary Tables'!G45>=5,'Summary Tables'!F45>0),"⚠ High — Exceptions + Missed Discount",IF('Summary Tables'!G45>=5,"⚠ High — Multiple Exceptions",IF('Summary Tables'!F45>50,"⚠ Review — Missed Discount",IF('Summary Tables'!C45>10000,"► Monitor — High Balance","✓ Normal")))) -> ✓ Normal
B11: ='Summary Tables'!B46 -> Metro Packaging | C11: ='Summary Tables'!C46 -> 4829.39 | D11: ='Summary Tables'!D46 -> 8 | E11: ='Summary Tables'!E46 -> 4 | F11: ='Summary Tables'!F46 -> 100.9 | G11: ='Summary Tables'!G46 -> 1 | H11: =IF(AND('Summary Tables'!G46>=5,'Summary Tables'!F46>0),"⚠ High — Exceptions + Missed Discount",IF('Summary Tables'!G46>=5,"⚠ High — Multiple Exceptions",IF('Summary Tables'!F46>50,"⚠ Review — Missed Discount",IF('Summary Tables'!C46>10000,"► Monitor — High Balance","✓ Normal")))) -> ⚠ Review — Missed Discount
B12: ='Summary Tables'!B47 -> Northside Transport | C12: ='Summary Tables'!C47 -> 3607.89 | D12: ='Summary Tables'!D47 -> 9 | E12: ='Summary Tables'!E47 -> 1 | F12: ='Summary Tables'!F47 -> 0 | G12: ='Summary Tables'!G47 -> 0 | H12: =IF(AND('Summary Tables'!G47>=5,'Summary Tables'!F47>0),"⚠ High — Exceptions + Missed Discount",IF('Summary Tables'!G47>=5,"⚠ High — Multiple Exceptions",IF('Summary Tables'!F47>50,"⚠ Review — Missed Discount",IF('Summary Tables'!C47>10000,"► Monitor — High Balance","✓ Normal")))) -> ✓ Normal
B13: ='Summary Tables'!B48 -> City Utilities | C13: ='Summary Tables'!C48 -> 3052.83 | D13: ='Summary Tables'!D48 -> 10 | E13: ='Summary Tables'!E48 -> 5 | F13: ='Summary Tables'!F48 -> 0 | G13: ='Summary Tables'!G48 -> 1 | H13: =IF(AND('Summary Tables'!G48>=5,'Summary Tables'!F48>0),"⚠ High — Exceptions + Missed Discount",IF('Summary Tables'!G48>=5,"⚠ High — Multiple Exceptions",IF('Summary Tables'!F48>50,"⚠ Review — Missed Discount",IF('Summary Tables'!C48>10000,"► Monitor — High Balance","✓ Normal")))) -> ✓ Normal
B14: ='Summary Tables'!B49 -> Suministros MX | C14: ='Summary Tables'!C49 -> 2740.86 | D14: ='Summary Tables'!D49 -> 6 | E14: ='Summary Tables'!E49 -> 3 | F14: ='Summary Tables'!F49 -> 0 | G14: ='Summary Tables'!G49 -> 2 | H14: =IF(AND('Summary Tables'!G49>=5,'Summary Tables'!F49>0),"⚠ High — Exceptions + Missed Discount",IF('Summary Tables'!G49>=5,"⚠ High — Multiple Exceptions",IF('Summary Tables'!F49>50,"⚠ Review — Missed Discount",IF('Summary Tables'!C49>10000,"► Monitor — High Balance","✓ Normal")))) -> ✓ Normal
B15: ='Summary Tables'!B50 -> Packaging World | C15: ='Summary Tables'!C50 -> 2493.11 | D15: ='Summary Tables'!D50 -> 10 | E15: ='Summary Tables'!E50 -> 3 | F15: ='Summary Tables'!F50 -> 0 | G15: ='Summary Tables'!G50 -> 2 | H15: =IF(AND('Summary Tables'!G50>=5,'Summary Tables'!F50>0),"⚠ High — Exceptions + Missed Discount",IF('Summary Tables'!G50>=5,"⚠ High — Multiple Exceptions",IF('Summary Tables'!F50>50,"⚠ Review — Missed Discount",IF('Summary Tables'!C50>10000,"► Monitor — High Balance","✓ Normal")))) -> ✓ Normal
B16: ='Summary Tables'!B51 -> Office Supply Co | C16: ='Summary Tables'!C51 -> 2483.09 | D16: ='Summary Tables'!D51 -> 10 | E16: ='Summary Tables'!E51 -> 5 | F16: ='Summary Tables'!F51 -> 0 | G16: ='Summary Tables'!G51 -> 0 | H16: =IF(AND('Summary Tables'!G51>=5,'Summary Tables'!F51>0),"⚠ High — Exceptions + Missed Discount",IF('Summary Tables'!G51>=5,"⚠ High — Multiple Exceptions",IF('Summary Tables'!F51>50,"⚠ Review — Missed Discount",IF('Summary Tables'!C51>10000,"► Monitor — High Balance","✓ Normal")))) -> ✓ Normal
... B19: ='Summary Tables'!B54 -> Cleaning Solutions | C19: ='Summary Tables'!C54 -> 827.88 | D19: ='Summary Tables'!D54 -> 10 | E19: ='Summary Tables'!E54 -> 2 | F19: ='Summary Tables'!F54 -> 0 | G19: ='Summary Tables'!G54 -> 2 | H19: =IF(AND('Summary Tables'!G54>=5,'Summary Tables'!F54>0),"⚠ High — Exceptions + Missed Discount",IF('Summary Tables'!G54>=5,"⚠ High — Multiple Exceptions",IF('Summary Tables'!F54>50,"⚠ Review — Missed Discount",IF('Summary Tables'!C54>10000,"► Monitor — High Balance","✓ Normal")))) -> ✓ Normal

Sheet Formulas & Calculations
B1: Dashboard Formulas & Calculation Reference
B3: KPI / Metric | C3: Excel Formula (in Summary Tables) | D3: Source Column(s) | E3: Result
B4: KPI METRICS
B5: Total Outstanding (USD) | C5: =SUM(AP_Invoices[Outstanding USD]) | D5: outstanding_amount_usd = max(invoice_amount_usd − amount_paid_usd, 0) where both amounts are pre-converted to USD via fx_rate_used | E5: See Summary Tables D5
B6: On-Time Payment Rate | C6: =(COUNTIFS(AP_Invoices[Late Payment],FALSE(),AP_Invoices[Status],"Paid") +COUNTIFS(AP_Invoices[Late Payment],FALSE(),AP_Invoices[Status],"Partially Paid")) /(COUNTIF(AP_Invoices[Status],"Paid") +COUNTIF(AP_Invoices[Status],"Partially Paid")) | D6: late_payment_flag status | E6: See Summary Tables D7
B7: Discount Capture Rate | C7: =SUM(AP_Invoices[Disc Captured]) /(SUM(AP_Invoices[Disc Captured])+SUM(AP_Invoices[Disc Missed])) | D7: captured_discount_value missed_discount_value | E7: See Summary Tables D8
B8: Critical Exceptions | C8: =COUNTIF(AP_Invoices[Blocked 30d],TRUE()) +COUNTIF(AP_Invoices[Status],"Voided") +COUNTIF(AP_Invoices[In Review 15d],TRUE()) | D8: blocked_over_30_days status in_review_over_15_days | E8: See Summary Tables D9
B9: CHART DATA
B10: Aging — Outstanding by Bucket | C10: =SUMIF(AP_Invoices[Aging Bucket],<bucket>,AP_Invoices[Outstanding USD]) one formula per bucket row in Summary Tables C14:C18 | D10: aging_bucket outstanding_amount_usd | E10: Summary Tables C14:C18
B11: Discount — Captured by Month | C11: =SUMIF(AP_Invoices[Month],<month>,AP_Invoices[Disc Captured]) one formula per month row in summary tables C22:C27 | D11: posting_month_label captured_discount_value | E11: Summary Tables C22:C27
B12: Discount — Missed by Month | C12: =SUMIF(AP_Invoices[Month],<month>,AP_Invoices[Disc Missed]) one formula per month row in summary tables D22:D27 | D12: posting_month_label missed_discount_value | E12: Summary Tables D22:D27
B13: DERIVED FLAGS (computed in Python — Stage 2)
B14: late_payment_flag | C14: TRUE when status = "Paid", payment_date is not null, due_date is not null, and payment_date > due_date. Comparison is against due_date — not payment terms parsing. | D14: status payment_date due_date | E14: Boolean
B15: blocked_over_30_days | C15: TRUE when status = "Blocked" and (snapshot_date − posting_date) > 30 days. Status is used rather than raw payment_block presence because it more accurately reflects operational state. | D15: status posting_date snapshot_date | E15: Boolean
B16: in_review_over_15_days | C16: status = 'In Review' AND days_open_as_of_snapshot > 15 | D16: status days_open_as_of_snapshot | E16: Boolean
B17: aging_bucket | C17: Current = not overdue as of the snapshot date 0-30 Days = overdue; days_past_due between 1 and 30 31-60 Days = overdue; days_past_due between 31 and 60 61-90 Days = overdue; days_past_due between 61 and 90 90+ Days = overdue; days_past_due greater than 90 | D17: days_past_due snapshot_date due_date | E17: Categorical
B18: outstanding_amount_usd | C18: invoice_amount_usd = invoice_amount × fx_rate_used amount_paid_usd = amount_paid × fx_rate_used outstanding_amount_usd = max(invoice_amount_usd − amount_paid_usd, 0) Rounded to 2 decimal places. | D18: invoice_amount amount_paid fx_rate_used | E18: Numeric USD
B19: is_overdue | C19: OR([@Status]="Overdue", [@Status]="Blocked", [@Status]="In Review", AND([@Status]="Partially Paid", [@[Days Past Due]]>0)) | D19: Status Days Past Due | E19: Boolean — used in Vendor Overdue Count formulas

Sheet Project Pipeline
B1: Project Pipeline — End-to-End Data Flow
B3: Stage | C3: Description | D3: File / Reference
B4: STAGE 1 | C4: Data Source — Raw AP Records
C5: Raw AP invoice records simulating an ERP export (SAP / Oracle structure). 130 invoices · 57 columns · Jan – Jun 2025 4 company codes (US01, US02, US03, MX01) · 15 vendors · 3 currencies (USD, EUR, MXN) Includes invoice dates, due dates, payment dates, amounts, statuses, PO references. | D5: ap_invoices_raw.csv
B7: STAGE 2 | C7: Python / Pandas — Data Transformation
C8: Python script ingests the raw CSV and derives all calculated columns: • days_to_pay = payment_date − posting_date • outstanding_amount_usd = invoice_amount × fx_rate − amount_paid • aging_bucket from days_past_due thresholds (Current / 0-30 / 31-60 / 61-90 / 90+) • late_payment_flag, blocked_over_30_days, in_review_over_15_days • discount_captured_calc, captured_discount_value, missed_discount_value • urgency_level and issue_type classification Outputs the clean row-level CSV loaded into the Data sheet of this workbook. | D8: ap_pipeline.py → GitHub repo
B10: STAGE 3 | C10: SQL — Business Questions on Clean Data
C11: SQL queries written against the Stage 2 cleaned dataset to answer AP business questions: • Which vendors carry the highest outstanding balances and for how long? • What is the on-time payment rate by company code and fiscal period? • How much early-payment discount was lost and which vendors caused it? • Which invoices are blocked, voided, or in review beyond SLA thresholds? SQL runs on clean data — it answers questions, not transform raw data. Results cross-validate the KPI numbers in this dashboard. | D11: ap_analysis.sql → GitHub repo
B13: STAGE 4 | C13: Excel Dashboard — This Workbook
C14: Built with Python (openpyxl) to load the Data sheet, then Excel formulas do the work: • SUMIF / COUNTIF / COUNTIFS in Summary Tables aggregate all metrics • KPI cards on Dashboard reference Summary Tables via cell formulas • Charts are built from Summary Tables ranges — no hardcoded values • All formula logic documented in the Formulas & Calculations tab | D14: AP_Management_Dashboard.xlsx
